2025-01-27 20:45:21,774 - __main__ - INFO - Bot started
2025-01-27 20:45:21,774 - apscheduler.scheduler - INFO - Scheduler started
2025-01-27 20:45:22,168 - __main__ - INFO - New user started bot: 412692425 (hookah_nerz)
2025-01-27 20:45:51,649 - __main__ - INFO - New subscription added by user 412692425: premier
2025-01-27 20:46:07,430 - __main__ - ERROR - Error in add_subscription handler: There is no text in the message to edit
Traceback (most recent call last):
  File "C:\Users\User\Downloads\скрипт excel\main.py", line 77, in add_subscription
    query.edit_message_text("Введите название подписки:")
  File "C:\Users\User\Downloads\скрипт excel\test\lib\site-packages\telegram\callbackquery.py", line 216, in edit_message_text
    return self.message.edit_text(
  File "C:\Users\User\Downloads\скрипт excel\test\lib\site-packages\telegram\message.py", line 1935, in edit_text
    return self.bot.edit_message_text(
  File "C:\Users\User\Downloads\скрипт excel\test\lib\site-packages\telegram\bot.py", line 130, in decorator
    result = func(*args, **kwargs)
  File "C:\Users\User\Downloads\скрипт excel\test\lib\site-packages\telegram\bot.py", line 2582, in edit_message_text
    return self._message(
  File "C:\Users\User\Downloads\скрипт excel\test\lib\site-packages\telegram\ext\extbot.py", line 199, in _message
    result = super()._message(
  File "C:\Users\User\Downloads\скрипт excel\test\lib\site-packages\telegram\bot.py", line 332, in _message
    result = self._post(endpoint, data, timeout=timeout, api_kwargs=api_kwargs)
  File "C:\Users\User\Downloads\скрипт excel\test\lib\site-packages\telegram\bot.py", line 295, in _post
    return self.request.post(
  File "C:\Users\User\Downloads\скрипт excel\test\lib\site-packages\telegram\utils\request.py", line 356, in post
    result = self._request_wrapper(
  File "C:\Users\User\Downloads\скрипт excel\test\lib\site-packages\telegram\utils\request.py", line 279, in _request_wrapper
    raise BadRequest(message)
telegram.error.BadRequest: There is no text in the message to edit
2025-01-27 20:46:07,510 - __main__ - ERROR - Update {'update_id': 274806762, 'callback_query': {'data': 'add', 'chat_instance': '1593460746334233062', 'message': {'reply_markup': {'inline_keyboard': [[{'callback_data': 'add', 'text': '\u2795 Добавить подписку'}], [{'callback_data': 'list', 'text': '\U0001f4cb Список подписок'}], [{'callback_data': 'stats', 'text': '\U0001f4ca Статистика расходов'}], [{'callback_data': 'delete', 'text': '\u274c Удалить подписку'}]]}, 'delete_chat_photo': False, 'date': 1737999959, 'group_chat_created': False, 'caption_entities': [], 'supergroup_chat_created': False, 'chat': {'type': 'private', 'first_name': 'Nikita', 'id': 412692425, 'username': 'hookah_nerz'}, 'message_id': 10, 'photo': [{'width': 90, 'height': 51, 'file_size': 852, 'file_unique_id': 'AQADHO0xG7qvuEh4', 'file_id': 'AgACAgIAAxkDAAMKZ5fGV3aTtGA3Ft_efDpvhImY-awAAhztMRu6r7hIio3CcNbAmkQBAAMCAANzAAM2BA'}, {'width': 320, 'height': 182, 'file_size': 5516, 'file_unique_id': 'AQADHO0xG7qvuEhy', 'file_id': 'AgACAgIAAxkDAAMKZ5fGV3aTtGA3Ft_efDpvhImY-awAAhztMRu6r7hIio3CcNbAmkQBAAMCAANtAAM2BA'}, {'width': 800, 'height': 456, 'file_size': 17705, 'file_unique_id': 'AQADHO0xG7qvuEh9', 'file_id': 'AgACAgIAAxkDAAMKZ5fGV3aTtGA3Ft_efDpvhImY-awAAhztMRu6r7hIio3CcNbAmkQBAAMCAAN4AAM2BA'}, {'width': 850, 'height': 485, 'file_size': 18199, 'file_unique_id': 'AQADHO0xG7qvuEh-', 'file_id': 'AgACAgIAAxkDAAMKZ5fGV3aTtGA3Ft_efDpvhImY-awAAhztMRu6r7hIio3CcNbAmkQBAAMCAAN5AAM2BA'}], 'channel_chat_created': False, 'caption': '\U0001f4ca Статистика ваших расходов:', 'entities': [], 'new_chat_members': [], 'new_chat_photo': [], 'from': {'is_bot': True, 'id': 8039422153, 'first_name': 'testsheets', 'username': 'smoxsheets_bot'}}, 'id': '1772500470951646109', 'from': {'is_bot': False, 'language_code': 'ru', 'id': 412692425, 'first_name': 'Nikita', 'username': 'hookah_nerz'}}} caused error There is no text in the message to edit
Traceback (most recent call last):
  File "C:\Users\User\Downloads\скрипт excel\main.py", line 77, in add_subscription
    query.edit_message_text("Введите название подписки:")
  File "C:\Users\User\Downloads\скрипт excel\test\lib\site-packages\telegram\callbackquery.py", line 216, in edit_message_text
    return self.message.edit_text(
  File "C:\Users\User\Downloads\скрипт excel\test\lib\site-packages\telegram\message.py", line 1935, in edit_text
    return self.bot.edit_message_text(
  File "C:\Users\User\Downloads\скрипт excel\test\lib\site-packages\telegram\bot.py", line 130, in decorator
    result = func(*args, **kwargs)
  File "C:\Users\User\Downloads\скрипт excel\test\lib\site-packages\telegram\bot.py", line 2582, in edit_message_text
    return self._message(
  File "C:\Users\User\Downloads\скрипт excel\test\lib\site-packages\telegram\ext\extbot.py", line 199, in _message
    result = super()._message(
  File "C:\Users\User\Downloads\скрипт excel\test\lib\site-packages\telegram\bot.py", line 332, in _message
    result = self._post(endpoint, data, timeout=timeout, api_kwargs=api_kwargs)
  File "C:\Users\User\Downloads\скрипт excel\test\lib\site-packages\telegram\bot.py", line 295, in _post
    return self.request.post(
  File "C:\Users\User\Downloads\скрипт excel\test\lib\site-packages\telegram\utils\request.py", line 356, in post
    result = self._request_wrapper(
  File "C:\Users\User\Downloads\скрипт excel\test\lib\site-packages\telegram\utils\request.py", line 279, in _request_wrapper
    raise BadRequest(message)
telegram.error.BadRequest: There is no text in the message to edit

During handling of the above exception, another exception occurred:

Traceback (most recent call last):
  File "C:\Users\User\Downloads\скрипт excel\test\lib\site-packages\telegram\ext\dispatcher.py", line 555, in process_update
    handler.handle_update(update, self, check, context)
  File "C:\Users\User\Downloads\скрипт excel\test\lib\site-packages\telegram\ext\conversationhandler.py", line 626, in handle_update
    new_state = handler.handle_update(update, dispatcher, check_result, context)
  File "C:\Users\User\Downloads\скрипт excel\test\lib\site-packages\telegram\ext\handler.py", line 198, in handle_update
    return self.callback(update, context)
  File "C:\Users\User\Downloads\скрипт excel\main.py", line 81, in add_subscription
    query.edit_message_text("Произошла ошибка. Попробуйте позже.", reply_markup=main_menu())
  File "C:\Users\User\Downloads\скрипт excel\test\lib\site-packages\telegram\callbackquery.py", line 216, in edit_message_text
    return self.message.edit_text(
  File "C:\Users\User\Downloads\скрипт excel\test\lib\site-packages\telegram\message.py", line 1935, in edit_text
    return self.bot.edit_message_text(
  File "C:\Users\User\Downloads\скрипт excel\test\lib\site-packages\telegram\bot.py", line 130, in decorator
    result = func(*args, **kwargs)
  File "C:\Users\User\Downloads\скрипт excel\test\lib\site-packages\telegram\bot.py", line 2582, in edit_message_text
    return self._message(
  File "C:\Users\User\Downloads\скрипт excel\test\lib\site-packages\telegram\ext\extbot.py", line 199, in _message
    result = super()._message(
  File "C:\Users\User\Downloads\скрипт excel\test\lib\site-packages\telegram\bot.py", line 332, in _message
    result = self._post(endpoint, data, timeout=timeout, api_kwargs=api_kwargs)
  File "C:\Users\User\Downloads\скрипт excel\test\lib\site-packages\telegram\bot.py", line 295, in _post
    return self.request.post(
  File "C:\Users\User\Downloads\скрипт excel\test\lib\site-packages\telegram\utils\request.py", line 356, in post
    result = self._request_wrapper(
  File "C:\Users\User\Downloads\скрипт excel\test\lib\site-packages\telegram\utils\request.py", line 279, in _request_wrapper
    raise BadRequest(message)
telegram.error.BadRequest: There is no text in the message to edit
2025-01-27 20:46:28,059 - __main__ - INFO - New subscription added by user 412692425: google
2025-01-27 20:46:40,141 - __main__ - ERROR - Error in add_subscription handler: There is no text in the message to edit
Traceback (most recent call last):
  File "C:\Users\User\Downloads\скрипт excel\main.py", line 77, in add_subscription
    query.edit_message_text("Введите название подписки:")
  File "C:\Users\User\Downloads\скрипт excel\test\lib\site-packages\telegram\callbackquery.py", line 216, in edit_message_text
    return self.message.edit_text(
  File "C:\Users\User\Downloads\скрипт excel\test\lib\site-packages\telegram\message.py", line 1935, in edit_text
    return self.bot.edit_message_text(
  File "C:\Users\User\Downloads\скрипт excel\test\lib\site-packages\telegram\bot.py", line 130, in decorator
    result = func(*args, **kwargs)
  File "C:\Users\User\Downloads\скрипт excel\test\lib\site-packages\telegram\bot.py", line 2582, in edit_message_text
    return self._message(
  File "C:\Users\User\Downloads\скрипт excel\test\lib\site-packages\telegram\ext\extbot.py", line 199, in _message
    result = super()._message(
  File "C:\Users\User\Downloads\скрипт excel\test\lib\site-packages\telegram\bot.py", line 332, in _message
    result = self._post(endpoint, data, timeout=timeout, api_kwargs=api_kwargs)
  File "C:\Users\User\Downloads\скрипт excel\test\lib\site-packages\telegram\bot.py", line 295, in _post
    return self.request.post(
  File "C:\Users\User\Downloads\скрипт excel\test\lib\site-packages\telegram\utils\request.py", line 356, in post
    result = self._request_wrapper(
  File "C:\Users\User\Downloads\скрипт excel\test\lib\site-packages\telegram\utils\request.py", line 279, in _request_wrapper
    raise BadRequest(message)
telegram.error.BadRequest: There is no text in the message to edit
2025-01-27 20:46:40,204 - __main__ - ERROR - Update {'update_id': 274806768, 'callback_query': {'data': 'add', 'chat_instance': '1593460746334233062', 'message': {'reply_markup': {'inline_keyboard': [[{'callback_data': 'add', 'text': '\u2795 Добавить подписку'}], [{'callback_data': 'list', 'text': '\U0001f4cb Список подписок'}], [{'callback_data': 'stats', 'text': '\U0001f4ca Статистика расходов'}], [{'callback_data': 'delete', 'text': '\u274c Удалить подписку'}]]}, 'delete_chat_photo': False, 'date': 1737999989, 'group_chat_created': False, 'caption_entities': [], 'supergroup_chat_created': False, 'chat': {'type': 'private', 'first_name': 'Nikita', 'id': 412692425, 'username': 'hookah_nerz'}, 'message_id': 18, 'photo': [{'width': 90, 'height': 51, 'file_size': 1009, 'file_unique_id': 'AQADHu0xG7qvuEh4', 'file_id': 'AgACAgIAAxkDAAMSZ5fGdS2cfIkYKCgqQPeTGoGBvXEAAh7tMRu6r7hI2odHHiIHtpoBAAMCAANzAAM2BA'}, {'width': 320, 'height': 181, 'file_size': 6043, 'file_unique_id': 'AQADHu0xG7qvuEhy', 'file_id': 'AgACAgIAAxkDAAMSZ5fGdS2cfIkYKCgqQPeTGoGBvXEAAh7tMRu6r7hI2odHHiIHtpoBAAMCAANtAAM2BA'}, {'width': 800, 'height': 452, 'file_size': 18778, 'file_unique_id': 'AQADHu0xG7qvuEh9', 'file_id': 'AgACAgIAAxkDAAMSZ5fGdS2cfIkYKCgqQPeTGoGBvXEAAh7tMRu6r7hI2odHHiIHtpoBAAMCAAN4AAM2BA'}, {'width': 859, 'height': 485, 'file_size': 19325, 'file_unique_id': 'AQADHu0xG7qvuEh-', 'file_id': 'AgACAgIAAxkDAAMSZ5fGdS2cfIkYKCgqQPeTGoGBvXEAAh7tMRu6r7hI2odHHiIHtpoBAAMCAAN5AAM2BA'}], 'channel_chat_created': False, 'caption': '\U0001f4ca Статистика ваших расходов:', 'entities': [], 'new_chat_members': [], 'new_chat_photo': [], 'from': {'is_bot': True, 'id': 8039422153, 'first_name': 'testsheets', 'username': 'smoxsheets_bot'}}, 'id': '1772500469129898746', 'from': {'is_bot': False, 'language_code': 'ru', 'id': 412692425, 'first_name': 'Nikita', 'username': 'hookah_nerz'}}} caused error There is no text in the message to edit
Traceback (most recent call last):
  File "C:\Users\User\Downloads\скрипт excel\main.py", line 77, in add_subscription
    query.edit_message_text("Введите название подписки:")
  File "C:\Users\User\Downloads\скрипт excel\test\lib\site-packages\telegram\callbackquery.py", line 216, in edit_message_text
    return self.message.edit_text(
  File "C:\Users\User\Downloads\скрипт excel\test\lib\site-packages\telegram\message.py", line 1935, in edit_text
    return self.bot.edit_message_text(
  File "C:\Users\User\Downloads\скрипт excel\test\lib\site-packages\telegram\bot.py", line 130, in decorator
    result = func(*args, **kwargs)
  File "C:\Users\User\Downloads\скрипт excel\test\lib\site-packages\telegram\bot.py", line 2582, in edit_message_text
    return self._message(
  File "C:\Users\User\Downloads\скрипт excel\test\lib\site-packages\telegram\ext\extbot.py", line 199, in _message
    result = super()._message(
  File "C:\Users\User\Downloads\скрипт excel\test\lib\site-packages\telegram\bot.py", line 332, in _message
    result = self._post(endpoint, data, timeout=timeout, api_kwargs=api_kwargs)
  File "C:\Users\User\Downloads\скрипт excel\test\lib\site-packages\telegram\bot.py", line 295, in _post
    return self.request.post(
  File "C:\Users\User\Downloads\скрипт excel\test\lib\site-packages\telegram\utils\request.py", line 356, in post
    result = self._request_wrapper(
  File "C:\Users\User\Downloads\скрипт excel\test\lib\site-packages\telegram\utils\request.py", line 279, in _request_wrapper
    raise BadRequest(message)
telegram.error.BadRequest: There is no text in the message to edit

During handling of the above exception, another exception occurred:

Traceback (most recent call last):
  File "C:\Users\User\Downloads\скрипт excel\test\lib\site-packages\telegram\ext\dispatcher.py", line 555, in process_update
    handler.handle_update(update, self, check, context)
  File "C:\Users\User\Downloads\скрипт excel\test\lib\site-packages\telegram\ext\conversationhandler.py", line 626, in handle_update
    new_state = handler.handle_update(update, dispatcher, check_result, context)
  File "C:\Users\User\Downloads\скрипт excel\test\lib\site-packages\telegram\ext\handler.py", line 198, in handle_update
    return self.callback(update, context)
  File "C:\Users\User\Downloads\скрипт excel\main.py", line 81, in add_subscription
    query.edit_message_text("Произошла ошибка. Попробуйте позже.", reply_markup=main_menu())
  File "C:\Users\User\Downloads\скрипт excel\test\lib\site-packages\telegram\callbackquery.py", line 216, in edit_message_text
    return self.message.edit_text(
  File "C:\Users\User\Downloads\скрипт excel\test\lib\site-packages\telegram\message.py", line 1935, in edit_text
    return self.bot.edit_message_text(
  File "C:\Users\User\Downloads\скрипт excel\test\lib\site-packages\telegram\bot.py", line 130, in decorator
    result = func(*args, **kwargs)
  File "C:\Users\User\Downloads\скрипт excel\test\lib\site-packages\telegram\bot.py", line 2582, in edit_message_text
    return self._message(
  File "C:\Users\User\Downloads\скрипт excel\test\lib\site-packages\telegram\ext\extbot.py", line 199, in _message
    result = super()._message(
  File "C:\Users\User\Downloads\скрипт excel\test\lib\site-packages\telegram\bot.py", line 332, in _message
    result = self._post(endpoint, data, timeout=timeout, api_kwargs=api_kwargs)
  File "C:\Users\User\Downloads\скрипт excel\test\lib\site-packages\telegram\bot.py", line 295, in _post
    return self.request.post(
  File "C:\Users\User\Downloads\скрипт excel\test\lib\site-packages\telegram\utils\request.py", line 356, in post
    result = self._request_wrapper(
  File "C:\Users\User\Downloads\скрипт excel\test\lib\site-packages\telegram\utils\request.py", line 279, in _request_wrapper
    raise BadRequest(message)
telegram.error.BadRequest: There is no text in the message to edit
2025-01-27 20:46:59,935 - __main__ - INFO - New subscription added by user 412692425: avito
2025-01-27 20:47:56,898 - telegram.ext.updater - INFO - Received signal 2 (SIGINT), stopping...
2025-01-27 20:47:56,906 - apscheduler.scheduler - INFO - Scheduler has been shut down
2025-01-27 20:49:24,601 - __main__ - CRITICAL - Critical error in main: unbound method datetime.time() needs an argument
Traceback (most recent call last):
  File "C:\Users\User\Downloads\скрипт excel\main.py", line 239, in main
    job_queue.run_daily(check_subscriptions_for_reminders, time=datetime.time(hour=9, minute=0, second=0))  # Например, в 9:00
TypeError: unbound method datetime.time() needs an argument
2025-01-27 20:49:29,074 - __main__ - CRITICAL - Critical error in main: unbound method datetime.time() needs an argument
Traceback (most recent call last):
  File "C:\Users\User\Downloads\скрипт excel\main.py", line 239, in main
    job_queue.run_daily(check_subscriptions_for_reminders, time=datetime.time(hour=9, minute=0, second=0))  # Например, в 9:00
TypeError: unbound method datetime.time() needs an argument
2025-01-27 20:53:39,858 - __main__ - INFO - Starting bot initialization
2025-01-27 20:53:39,860 - __main__ - CRITICAL - Critical error in main: Invalid token
Traceback (most recent call last):
  File "C:\Users\User\Downloads\скрипт excel\main.py", line 282, in main
    updater = Updater(TOKEN)
  File "C:\Users\User\Downloads\скрипт excel\test\lib\site-packages\telegram\ext\updater.py", line 279, in __init__
    self.bot = ExtBot(
  File "C:\Users\User\Downloads\скрипт excel\test\lib\site-packages\telegram\ext\extbot.py", line 97, in __init__
    super().__init__(
  File "C:\Users\User\Downloads\скрипт excel\test\lib\site-packages\telegram\bot.py", line 191, in __init__
    self.token = self._validate_token(token)
  File "C:\Users\User\Downloads\скрипт excel\test\lib\site-packages\telegram\bot.py", line 351, in _validate_token
    raise InvalidToken()
telegram.error.InvalidToken: Invalid token
2025-01-27 20:54:27,131 - __main__ - INFO - Starting bot initialization
2025-01-27 20:54:27,132 - __main__ - CRITICAL - Critical error in main: unbound method datetime.time() needs an argument
Traceback (most recent call last):
  File "C:\Users\User\Downloads\скрипт excel\main.py", line 287, in main
    job_queue.run_daily(check_subscriptions_for_reminders, time=datetime.time(hour=9, minute=0, second=0))
TypeError: unbound method datetime.time() needs an argument
2025-01-27 21:00:56,341 - __main__ - INFO - Starting bot initialization
2025-01-27 21:00:56,343 - __main__ - CRITICAL - Critical error in main: descriptor 'time' for 'datetime.datetime' objects doesn't apply to a 'int' object
Traceback (most recent call last):
  File "C:\Users\User\Downloads\скрипт excel\main.py", line 287, in main
    reminder_time = datetime.time(9, 0, 0)  # 9:00:00
TypeError: descriptor 'time' for 'datetime.datetime' objects doesn't apply to a 'int' object
2025-01-27 21:14:13,582 - __main__ - INFO - Starting bot initialization
2025-01-27 21:14:13,625 - apscheduler.scheduler - INFO - Adding job tentatively -- it will be properly scheduled when the scheduler starts
2025-01-27 21:14:13,627 - __main__ - INFO - Bot started
2025-01-27 21:14:13,628 - apscheduler.scheduler - INFO - Added job "check_subscriptions_for_reminders" to job store "default"
2025-01-27 21:14:13,629 - apscheduler.scheduler - INFO - Scheduler started
2025-01-27 21:14:41,490 - __main__ - ERROR - Error in list_subscriptions handler: There is no text in the message to edit
Traceback (most recent call last):
  File "C:\Users\User\Downloads\скрипт excel\main.py", line 151, in list_subscriptions
    query.edit_message_text(response, reply_markup=main_menu())
  File "C:\Users\User\Downloads\скрипт excel\test\lib\site-packages\telegram\callbackquery.py", line 216, in edit_message_text
    return self.message.edit_text(
  File "C:\Users\User\Downloads\скрипт excel\test\lib\site-packages\telegram\message.py", line 1935, in edit_text
    return self.bot.edit_message_text(
  File "C:\Users\User\Downloads\скрипт excel\test\lib\site-packages\telegram\bot.py", line 130, in decorator
    result = func(*args, **kwargs)
  File "C:\Users\User\Downloads\скрипт excel\test\lib\site-packages\telegram\bot.py", line 2582, in edit_message_text
    return self._message(
  File "C:\Users\User\Downloads\скрипт excel\test\lib\site-packages\telegram\ext\extbot.py", line 199, in _message
    result = super()._message(
  File "C:\Users\User\Downloads\скрипт excel\test\lib\site-packages\telegram\bot.py", line 332, in _message
    result = self._post(endpoint, data, timeout=timeout, api_kwargs=api_kwargs)
  File "C:\Users\User\Downloads\скрипт excel\test\lib\site-packages\telegram\bot.py", line 295, in _post
    return self.request.post(
  File "C:\Users\User\Downloads\скрипт excel\test\lib\site-packages\telegram\utils\request.py", line 356, in post
    result = self._request_wrapper(
  File "C:\Users\User\Downloads\скрипт excel\test\lib\site-packages\telegram\utils\request.py", line 279, in _request_wrapper
    raise BadRequest(message)
telegram.error.BadRequest: There is no text in the message to edit
2025-01-27 21:14:41,560 - __main__ - ERROR - Update {'callback_query': {'id': '1772500469524731841', 'chat_instance': '1593460746334233062', 'data': 'list', 'message': {'group_chat_created': False, 'date': 1738001677, 'new_chat_photo': [], 'chat': {'type': 'private', 'first_name': 'Nikita', 'username': 'hookah_nerz', 'id': 412692425}, 'new_chat_members': [], 'caption': '\U0001f4ca Статистика ваших расходов:', 'photo': [{'height': 51, 'file_size': 1066, 'file_unique_id': 'AQADIe0xG7qvuEh4', 'file_id': 'AgACAgIAAxkDAAMbZ5fGlYIxDaawnc2wXsAbbL1Ly8oAAiHtMRu6r7hI4xLZmIGFhnwBAAMCAANzAAM2BA', 'width': 90}, {'height': 181, 'file_size': 6837, 'file_unique_id': 'AQADIe0xG7qvuEhy', 'file_id': 'AgACAgIAAxkDAAMbZ5fGlYIxDaawnc2wXsAbbL1Ly8oAAiHtMRu6r7hI4xLZmIGFhnwBAAMCAANtAAM2BA', 'width': 320}, {'height': 452, 'file_size': 21206, 'file_unique_id': 'AQADIe0xG7qvuEh9', 'file_id': 'AgACAgIAAxkDAAMbZ5fGlYIxDaawnc2wXsAbbL1Ly8oAAiHtMRu6r7hI4xLZmIGFhnwBAAMCAAN4AAM2BA', 'width': 800}, {'height': 485, 'file_size': 21945, 'file_unique_id': 'AQADIe0xG7qvuEh-', 'file_id': 'AgACAgIAAxkDAAMbZ5fGlYIxDaawnc2wXsAbbL1Ly8oAAiHtMRu6r7hI4xLZmIGFhnwBAAMCAAN5AAM2BA', 'width': 859}], 'supergroup_chat_created': False, 'reply_markup': {'inline_keyboard': [[{'text': '\u2795 Добавить подписку', 'callback_data': 'add'}], [{'text': '\U0001f4cb Список подписок', 'callback_data': 'list'}], [{'text': '\U0001f4ca Статистика расходов', 'callback_data': 'stats'}], [{'text': '\u274c Удалить подписку', 'callback_data': 'delete'}]]}, 'message_id': 28, 'entities': [], 'delete_chat_photo': False, 'channel_chat_created': False, 'caption_entities': [], 'from': {'id': 8039422153, 'is_bot': True, 'first_name': 'testsheets', 'username': 'smoxsheets_bot'}}, 'from': {'id': 412692425, 'is_bot': False, 'language_code': 'ru', 'first_name': 'Nikita', 'username': 'hookah_nerz'}}, 'update_id': 274806777} caused error There is no text in the message to edit
Traceback (most recent call last):
  File "C:\Users\User\Downloads\скрипт excel\main.py", line 151, in list_subscriptions
    query.edit_message_text(response, reply_markup=main_menu())
  File "C:\Users\User\Downloads\скрипт excel\test\lib\site-packages\telegram\callbackquery.py", line 216, in edit_message_text
    return self.message.edit_text(
  File "C:\Users\User\Downloads\скрипт excel\test\lib\site-packages\telegram\message.py", line 1935, in edit_text
    return self.bot.edit_message_text(
  File "C:\Users\User\Downloads\скрипт excel\test\lib\site-packages\telegram\bot.py", line 130, in decorator
    result = func(*args, **kwargs)
  File "C:\Users\User\Downloads\скрипт excel\test\lib\site-packages\telegram\bot.py", line 2582, in edit_message_text
    return self._message(
  File "C:\Users\User\Downloads\скрипт excel\test\lib\site-packages\telegram\ext\extbot.py", line 199, in _message
    result = super()._message(
  File "C:\Users\User\Downloads\скрипт excel\test\lib\site-packages\telegram\bot.py", line 332, in _message
    result = self._post(endpoint, data, timeout=timeout, api_kwargs=api_kwargs)
  File "C:\Users\User\Downloads\скрипт excel\test\lib\site-packages\telegram\bot.py", line 295, in _post
    return self.request.post(
  File "C:\Users\User\Downloads\скрипт excel\test\lib\site-packages\telegram\utils\request.py", line 356, in post
    result = self._request_wrapper(
  File "C:\Users\User\Downloads\скрипт excel\test\lib\site-packages\telegram\utils\request.py", line 279, in _request_wrapper
    raise BadRequest(message)
telegram.error.BadRequest: There is no text in the message to edit

During handling of the above exception, another exception occurred:

Traceback (most recent call last):
  File "C:\Users\User\Downloads\скрипт excel\test\lib\site-packages\telegram\ext\dispatcher.py", line 555, in process_update
    handler.handle_update(update, self, check, context)
  File "C:\Users\User\Downloads\скрипт excel\test\lib\site-packages\telegram\ext\handler.py", line 198, in handle_update
    return self.callback(update, context)
  File "C:\Users\User\Downloads\скрипт excel\main.py", line 154, in list_subscriptions
    query.edit_message_text("Произошла ошибка. Попробуйте позже.", reply_markup=main_menu())
  File "C:\Users\User\Downloads\скрипт excel\test\lib\site-packages\telegram\callbackquery.py", line 216, in edit_message_text
    return self.message.edit_text(
  File "C:\Users\User\Downloads\скрипт excel\test\lib\site-packages\telegram\message.py", line 1935, in edit_text
    return self.bot.edit_message_text(
  File "C:\Users\User\Downloads\скрипт excel\test\lib\site-packages\telegram\bot.py", line 130, in decorator
    result = func(*args, **kwargs)
  File "C:\Users\User\Downloads\скрипт excel\test\lib\site-packages\telegram\bot.py", line 2582, in edit_message_text
    return self._message(
  File "C:\Users\User\Downloads\скрипт excel\test\lib\site-packages\telegram\ext\extbot.py", line 199, in _message
    result = super()._message(
  File "C:\Users\User\Downloads\скрипт excel\test\lib\site-packages\telegram\bot.py", line 332, in _message
    result = self._post(endpoint, data, timeout=timeout, api_kwargs=api_kwargs)
  File "C:\Users\User\Downloads\скрипт excel\test\lib\site-packages\telegram\bot.py", line 295, in _post
    return self.request.post(
  File "C:\Users\User\Downloads\скрипт excel\test\lib\site-packages\telegram\utils\request.py", line 356, in post
    result = self._request_wrapper(
  File "C:\Users\User\Downloads\скрипт excel\test\lib\site-packages\telegram\utils\request.py", line 279, in _request_wrapper
    raise BadRequest(message)
telegram.error.BadRequest: There is no text in the message to edit
2025-01-27 21:45:20,862 - telegram.ext.updater - INFO - Received signal 2 (SIGINT), stopping...
2025-01-27 21:45:20,886 - apscheduler.scheduler - INFO - Scheduler has been shut down
2025-01-27 21:45:35,777 - __main__ - INFO - Starting bot initialization
2025-01-27 21:45:35,894 - apscheduler.scheduler - INFO - Adding job tentatively -- it will be properly scheduled when the scheduler starts
2025-01-27 21:45:35,901 - __main__ - INFO - Bot started
2025-01-27 21:45:35,902 - apscheduler.scheduler - INFO - Added job "check_subscriptions_for_reminders" to job store "default"
2025-01-27 21:45:35,902 - apscheduler.scheduler - INFO - Scheduler started
2025-01-27 22:31:50,995 - telegram.ext.updater - INFO - Received signal 2 (SIGINT), stopping...
2025-01-27 22:31:51,121 - apscheduler.scheduler - INFO - Scheduler has been shut down
